2025-10-23T21:30:18.000000000Z [inf]  Starting Container
2025-10-23T21:30:21.525914092Z [err]  Traceback (most recent call last):
2025-10-23T21:30:21.525920232Z [err]    File "/usr/local/bin/uvicorn", line 8, in <module>
2025-10-23T21:30:21.525927622Z [err]      sys.exit(main())
2025-10-23T21:30:21.525932117Z [err]               ^^^^^^
2025-10-23T21:30:21.525936540Z [err]    File "/usr/local/lib/python3.11/site-packages/click/core.py", line 1462, in __call__
2025-10-23T21:30:21.525941281Z [err]      return self.main(*args, **kwargs)
2025-10-23T21:30:21.525945700Z [err]             ^^^^^^^^^^^^^^^^^^^^^^^^^^
2025-10-23T21:30:21.525949950Z [err]    File "/usr/local/lib/python3.11/site-packages/click/core.py", line 1383, in main
2025-10-23T21:30:21.525953820Z [err]      rv = self.invoke(ctx)
2025-10-23T21:30:21.525962412Z [err]           ^^^^^^^^^^^^^^^^
2025-10-23T21:30:21.526106776Z [err]    File "/usr/local/lib/python3.11/site-packages/click/core.py", line 1246, in invoke
2025-10-23T21:30:21.526116807Z [err]      return ctx.invoke(self.callback, **ctx.params)
2025-10-23T21:30:21.526124537Z [err]             ^^^^^^^^^^^^^^^^^^^^^^^^^^^^^^^^^^^^^^^
2025-10-23T21:30:21.526130205Z [err]    File "/usr/local/lib/python3.11/site-packages/click/core.py", line 814, in invoke
2025-10-23T21:30:21.526137296Z [err]      return callback(*args, **kwargs)
2025-10-23T21:30:21.526143392Z [err]             ^^^^^^^^^^^^^^^^^^^^^^^^^
2025-10-23T21:30:21.526149039Z [err]    File "/usr/local/lib/python3.11/site-packages/uvicorn/main.py", line 423, in main
2025-10-23T21:30:21.526153566Z [err]      run(
2025-10-23T21:30:21.526157594Z [err]    File "/usr/local/lib/python3.11/site-packages/uvicorn/main.py", line 593, in run
2025-10-23T21:30:21.526162240Z [err]      server.run()
2025-10-23T21:30:21.526166480Z [err]    File "/usr/local/lib/python3.11/site-packages/uvicorn/server.py", line 67, in run
2025-10-23T21:30:21.526173589Z [err]      return asyncio_run(self.serve(sockets=sockets), loop_factory=self.config.get_loop_factory())
2025-10-23T21:30:21.527793972Z [err]      return self._loop.run_until_complete(task)
2025-10-23T21:30:21.527799113Z [err]                        ^^^^^^^^^^^^^^^^^^^^^^^^^^^^
2025-10-23T21:30:21.527800156Z [err]               ^^^^^^^^^^^^^^^^^^^^^^^^^^^^^^^^^^^
2025-10-23T21:30:21.527804483Z [err]      await self._serve(sockets)
2025-10-23T21:30:21.527806532Z [err]             ^^^^^^^^^^^^^^^^^^^^^^^^^^^^^^^^^^^
2025-10-23T21:30:21.527814266Z [err]    File "/usr/local/lib/python3.11/site-packages/uvicorn/importer.py", line 19, in import_from_string
2025-10-23T21:30:21.527817873Z [err]    File "/usr/local/lib/python3.11/importlib/__init__.py", line 126, in import_module
2025-10-23T21:30:21.527819506Z [err]    File "/usr/local/lib/python3.11/asyncio/base_events.py", line 654, in run_until_complete
2025-10-23T21:30:21.527824374Z [err]    File "/usr/local/lib/python3.11/site-packages/uvicorn/server.py", line 78, in _serve
2025-10-23T21:30:21.527831376Z [err]      module = importlib.import_module(module_str)
2025-10-23T21:30:21.527831874Z [err]      return future.result()
2025-10-23T21:30:21.527840785Z [err]             ^^^^^^^^^^^^^^^
2025-10-23T21:30:21.527846575Z [err]      config.load()
2025-10-23T21:30:21.527853114Z [err]    File "/usr/local/lib/python3.11/site-packages/uvicorn/server.py", line 71, in serve
2025-10-23T21:30:21.527854478Z [err]             ^^^^^^^^^^^^^^^^^^^^^^^^^^^^^^^^^^^^^^^^^^^^^^^^^^^^^^^^^^^^^^^^^^^^^^^^^^^^^^^^^^^^^
2025-10-23T21:30:21.527861434Z [err]    File "/usr/local/lib/python3.11/site-packages/uvicorn/_compat.py", line 30, in asyncio_run
2025-10-23T21:30:21.527869512Z [err]      return runner.run(main)
2025-10-23T21:30:21.527869786Z [err]    File "/usr/local/lib/python3.11/site-packages/uvicorn/config.py", line 439, in load
2025-10-23T21:30:21.527886843Z [err]             ^^^^^^^^^^^^^^^^
2025-10-23T21:30:21.527887910Z [err]      self.loaded_app = import_from_string(self.app)
2025-10-23T21:30:21.527897648Z [err]    File "/usr/local/lib/python3.11/asyncio/runners.py", line 118, in run
2025-10-23T21:30:21.529957892Z [err]    File "/app/app/main.py", line 20, in <module>
2025-10-23T21:30:21.529967330Z [err]      from app.api.gdrive_ops import router as gdrive_router # New import for Google Drive
2025-10-23T21:30:21.529993104Z [err]      ^^^^^^^^^^^^^^^^^^^^^^^^^^^^^^^^^^^^^^^^^^^^^^^^^^^^^^
2025-10-23T21:30:21.530000550Z [err]    File "/app/app/api/gdrive_ops/router.py", line 2, in <module>
2025-10-23T21:30:21.530006536Z [err]      from .sync import run_google_drive_sync
2025-10-23T21:30:21.530013884Z [err]    File "/app/app/api/gdrive_ops/sync.py", line 12, in <module>
2025-10-23T21:30:21.530019274Z [err]      from app.api.file_ops.upload import upload_file_to_supabase
2025-10-23T21:30:21.530026903Z [err]  ImportError: cannot import name 'upload_file_to_supabase' from 'app.api.file_ops.upload' (/app/app/api/file_ops/upload.py)
2025-10-23T21:30:21.530105761Z [err]      return _bootstrap._gcd_import(name[level:], package, level)
2025-10-23T21:30:21.530110484Z [err]             ^^^^^^^^^^^^^^^^^^^^^^^^^^^^^^^^^^^^^^^^^^^^^^^^^^^^
2025-10-23T21:30:21.530115327Z [err]    File "<frozen importlib._bootstrap>", line 1204, in _gcd_import
2025-10-23T21:30:21.530119463Z [err]    File "<frozen importlib._bootstrap>", line 1176, in _find_and_load
2025-10-23T21:30:21.530123388Z [err]    File "<frozen importlib._bootstrap>", line 1147, in _find_and_load_unlocked
2025-10-23T21:30:21.530127561Z [err]    File "<frozen importlib._bootstrap>", line 690, in _load_unlocked
2025-10-23T21:30:21.530131760Z [err]    File "<frozen importlib._bootstrap_external>", line 940, in exec_module
2025-10-23T21:30:21.530140390Z [err]    File "<frozen importlib._bootstrap>", line 241, in _call_with_frames_removed
2025-10-23T21:30:27.036468139Z [err]           ^^^^^^^^^^^^^^^^
2025-10-23T21:30:27.036481436Z [err]    File "/usr/local/lib/python3.11/site-packages/click/core.py", line 1246, in invoke
2025-10-23T21:30:27.036491821Z [err]      return ctx.invoke(self.callback, **ctx.params)
2025-10-23T21:30:27.036498446Z [err]      rv = self.invoke(ctx)
2025-10-23T21:30:27.036569249Z [err]             ^^^^^^^^^^^^^^^^^^^^^^^^^
2025-10-23T21:30:27.036576231Z [err]    File "/usr/local/lib/python3.11/site-packages/uvicorn/main.py", line 423, in main
2025-10-23T21:30:27.036581496Z [err]      run(
2025-10-23T21:30:27.036587722Z [err]    File "/usr/local/lib/python3.11/site-packages/uvicorn/main.py", line 593, in run
2025-10-23T21:30:27.036595678Z [err]      server.run()
2025-10-23T21:30:27.036602983Z [err]    File "/usr/local/lib/python3.11/site-packages/uvicorn/server.py", line 67, in run
2025-10-23T21:30:27.036605307Z [err]             ^^^^^^^^^^^^^^^^^^^^^^^^^^^^^^^^^^^^^^^
2025-10-23T21:30:27.036610760Z [err]      return asyncio_run(self.serve(sockets=sockets), loop_factory=self.config.get_loop_factory())
2025-10-23T21:30:27.036655811Z [err]    File "/usr/local/lib/python3.11/site-packages/click/core.py", line 814, in invoke
2025-10-23T21:30:27.036670114Z [err]      return callback(*args, **kwargs)
2025-10-23T21:30:27.037169630Z [err]  Traceback (most recent call last):
2025-10-23T21:30:27.037435296Z [err]    File "/usr/local/bin/uvicorn", line 8, in <module>
2025-10-23T21:30:27.037442401Z [err]      sys.exit(main())
2025-10-23T21:30:27.037447458Z [err]               ^^^^^^
2025-10-23T21:30:27.037453175Z [err]    File "/usr/local/lib/python3.11/site-packages/click/core.py", line 1462, in __call__
2025-10-23T21:30:27.037459873Z [err]      return self.main(*args, **kwargs)
2025-10-23T21:30:27.037465586Z [err]             ^^^^^^^^^^^^^^^^^^^^^^^^^^
2025-10-23T21:30:27.037470886Z [err]    File "/usr/local/lib/python3.11/site-packages/click/core.py", line 1383, in main
2025-10-23T21:30:28.102948203Z [err]             ^^^^^^^^^^^^^^^^^^^^^^^^^^^^^^^^^^^^^^^^^^^^^^^^^^^^^^^^^^^^^^^^^^^^^^^^^^^^^^^^^^^^^
2025-10-23T21:30:28.102955944Z [err]    File "/usr/local/lib/python3.11/site-packages/uvicorn/_compat.py", line 30, in asyncio_run
2025-10-23T21:30:28.102961898Z [err]      return runner.run(main)
2025-10-23T21:30:28.102966842Z [err]             ^^^^^^^^^^^^^^^^
2025-10-23T21:30:28.102973751Z [err]    File "/usr/local/lib/python3.11/asyncio/runners.py", line 118, in run
2025-10-23T21:30:28.102979368Z [err]      return self._loop.run_until_complete(task)
2025-10-23T21:30:28.102984732Z [err]             ^^^^^^^^^^^^^^^^^^^^^^^^^^^^^^^^^^^
2025-10-23T21:30:28.102990315Z [err]    File "/usr/local/lib/python3.11/asyncio/base_events.py", line 654, in run_until_complete
2025-10-23T21:30:28.102995426Z [err]      return future.result()
2025-10-23T21:30:28.103000322Z [err]             ^^^^^^^^^^^^^^^
2025-10-23T21:30:28.103005756Z [err]    File "/usr/local/lib/python3.11/site-packages/uvicorn/server.py", line 71, in serve
2025-10-23T21:30:28.103011519Z [err]      await self._serve(sockets)
2025-10-23T21:30:28.103017359Z [err]    File "/usr/local/lib/python3.11/site-packages/uvicorn/server.py", line 78, in _serve
2025-10-23T21:30:28.103022205Z [err]      config.load()
2025-10-23T21:30:28.103028021Z [err]    File "/usr/local/lib/python3.11/site-packages/uvicorn/config.py", line 439, in load
2025-10-23T21:30:28.103034035Z [err]      self.loaded_app = import_from_string(self.app)
2025-10-23T21:30:28.103039666Z [err]                        ^^^^^^^^^^^^^^^^^^^^^^^^^^^^
2025-10-23T21:30:28.103046816Z [err]    File "/usr/local/lib/python3.11/site-packages/uvicorn/importer.py", line 19, in import_from_string
2025-10-23T21:30:28.103052672Z [err]      module = importlib.import_module(module_str)
2025-10-23T21:30:28.103058711Z [err]               ^^^^^^^^^^^^^^^^^^^^^^^^^^^^^^^^^^^
2025-10-23T21:30:28.103071314Z [err]    File "/usr/local/lib/python3.11/importlib/__init__.py", line 126, in import_module
2025-10-23T21:30:29.406422188Z [err]      return _bootstrap._gcd_import(name[level:], package, level)
2025-10-23T21:30:29.406427270Z [err]             ^^^^^^^^^^^^^^^^^^^^^^^^^^^^^^^^^^^^^^^^^^^^^^^^^^^^
2025-10-23T21:30:29.406432755Z [err]    File "<frozen importlib._bootstrap>", line 1204, in _gcd_import
2025-10-23T21:30:29.406890005Z [err]    File "<frozen importlib._bootstrap>", line 1176, in _find_and_load
2025-10-23T21:30:29.406905884Z [err]    File "<frozen importlib._bootstrap>", line 1147, in _find_and_load_unlocked
2025-10-23T21:30:29.406916499Z [err]    File "<frozen importlib._bootstrap>", line 690, in _load_unlocked
2025-10-23T21:30:29.406925751Z [err]    File "<frozen importlib._bootstrap_external>", line 940, in exec_module
2025-10-23T21:30:29.406935265Z [err]    File "<frozen importlib._bootstrap>", line 241, in _call_with_frames_removed
2025-10-23T21:30:29.406944549Z [err]    File "/app/app/main.py", line 20, in <module>
2025-10-23T21:30:29.406952919Z [err]      from app.api.gdrive_ops import router as gdrive_router # New import for Google Drive
2025-10-23T21:30:29.406961097Z [err]      ^^^^^^^^^^^^^^^^^^^^^^^^^^^^^^^^^^^^^^^^^^^^^^^^^^^^^^
2025-10-23T21:30:29.406968362Z [err]    File "/app/app/api/gdrive_ops/router.py", line 2, in <module>
2025-10-23T21:30:29.406975448Z [err]      from .sync import run_google_drive_sync
2025-10-23T21:30:29.406981894Z [err]    File "/app/app/api/gdrive_ops/sync.py", line 12, in <module>
2025-10-23T21:30:29.406988052Z [err]      from app.api.file_ops.upload import upload_file_to_supabase
2025-10-23T21:30:29.406994560Z [err]  ImportError: cannot import name 'upload_file_to_supabase' from 'app.api.file_ops.upload' (/app/app/api/file_ops/upload.py)
2025-10-23T21:30:32.415498428Z [err]      server.run()
2025-10-23T21:30:32.415500939Z [err]      sys.exit(main())
2025-10-23T21:30:32.415505877Z [err]    File "/usr/local/lib/python3.11/site-packages/uvicorn/server.py", line 67, in run
2025-10-23T21:30:32.415511535Z [err]      return asyncio_run(self.serve(sockets=sockets), loop_factory=self.config.get_loop_factory())
2025-10-23T21:30:32.415518025Z [err]    File "/usr/local/lib/python3.11/site-packages/uvicorn/main.py", line 423, in main
2025-10-23T21:30:32.415534893Z [err]      run(
2025-10-23T21:30:32.415563475Z [err]      rv = self.invoke(ctx)
2025-10-23T21:30:32.415578621Z [err]           ^^^^^^^^^^^^^^^^
2025-10-23T21:30:32.415578926Z [err]    File "/usr/local/lib/python3.11/site-packages/uvicorn/main.py", line 593, in run
2025-10-23T21:30:32.415602072Z [err]    File "/usr/local/lib/python3.11/site-packages/click/core.py", line 1246, in invoke
2025-10-23T21:30:32.415602754Z [err]    File "/usr/local/lib/python3.11/site-packages/click/core.py", line 814, in invoke
2025-10-23T21:30:32.415608425Z [err]               ^^^^^^
2025-10-23T21:30:32.415613725Z [err]      return callback(*args, **kwargs)
2025-10-23T21:30:32.415618901Z [err]      return ctx.invoke(self.callback, **ctx.params)
2025-10-23T21:30:32.415620083Z [err]    File "/usr/local/lib/python3.11/site-packages/click/core.py", line 1462, in __call__
2025-10-23T21:30:32.415624649Z [err]             ^^^^^^^^^^^^^^^^^^^^^^^^^
2025-10-23T21:30:32.415630572Z [err]      return self.main(*args, **kwargs)
2025-10-23T21:30:32.415630989Z [err]             ^^^^^^^^^^^^^^^^^^^^^^^^^^^^^^^^^^^^^^^
2025-10-23T21:30:32.415655325Z [err]             ^^^^^^^^^^^^^^^^^^^^^^^^^^
2025-10-23T21:30:32.415657822Z [err]  Traceback (most recent call last):
2025-10-23T21:30:32.415664993Z [err]    File "/usr/local/bin/uvicorn", line 8, in <module>
2025-10-23T21:30:32.415667983Z [err]    File "/usr/local/lib/python3.11/site-packages/click/core.py", line 1383, in main
2025-10-23T21:30:32.419572186Z [err]             ^^^^^^^^^^^^^^^^^^^^^^^^^^^^^^^^^^^^^^^^^^^^^^^^^^^^^^^^^^^^^^^^^^^^^^^^^^^^^^^^^^^^^
2025-10-23T21:30:32.419577836Z [err]    File "/usr/local/lib/python3.11/site-packages/uvicorn/_compat.py", line 30, in asyncio_run
2025-10-23T21:30:32.419583002Z [err]      return runner.run(main)
2025-10-23T21:30:32.419588295Z [err]             ^^^^^^^^^^^^^^^^
2025-10-23T21:30:32.419593794Z [err]    File "/usr/local/lib/python3.11/asyncio/runners.py", line 118, in run
2025-10-23T21:30:32.419599017Z [err]      return self._loop.run_until_complete(task)
2025-10-23T21:30:32.419605793Z [err]             ^^^^^^^^^^^^^^^^^^^^^^^^^^^^^^^^^^^
2025-10-23T21:30:32.419611070Z [err]    File "/usr/local/lib/python3.11/asyncio/base_events.py", line 654, in run_until_complete
2025-10-23T21:30:32.419616163Z [err]      return future.result()
2025-10-23T21:30:32.419621639Z [err]             ^^^^^^^^^^^^^^^
2025-10-23T21:30:32.419627294Z [err]    File "/usr/local/lib/python3.11/site-packages/uvicorn/server.py", line 71, in serve
2025-10-23T21:30:32.419632345Z [err]      await self._serve(sockets)
2025-10-23T21:30:32.419637729Z [err]    File "/usr/local/lib/python3.11/site-packages/uvicorn/server.py", line 78, in _serve
2025-10-23T21:30:32.419643020Z [err]      config.load()
2025-10-23T21:30:32.419648784Z [err]    File "/usr/local/lib/python3.11/site-packages/uvicorn/config.py", line 439, in load
2025-10-23T21:30:32.419653842Z [err]      self.loaded_app = import_from_string(self.app)
2025-10-23T21:30:32.419660339Z [err]                        ^^^^^^^^^^^^^^^^^^^^^^^^^^^^
2025-10-23T21:30:32.419665293Z [err]    File "/usr/local/lib/python3.11/site-packages/uvicorn/importer.py", line 19, in import_from_string
2025-10-23T21:30:32.419670097Z [err]      module = importlib.import_module(module_str)
2025-10-23T21:30:32.419674721Z [err]               ^^^^^^^^^^^^^^^^^^^^^^^^^^^^^^^^^^^
2025-10-23T21:30:32.419679758Z [err]    File "/usr/local/lib/python3.11/importlib/__init__.py", line 126, in import_module
2025-10-23T21:30:32.420957461Z [err]      return _bootstrap._gcd_import(name[level:], package, level)
2025-10-23T21:30:32.420963828Z [err]             ^^^^^^^^^^^^^^^^^^^^^^^^^^^^^^^^^^^^^^^^^^^^^^^^^^^^
2025-10-23T21:30:32.420970445Z [err]    File "<frozen importlib._bootstrap>", line 1204, in _gcd_import
2025-10-23T21:30:32.420976065Z [err]    File "<frozen importlib._bootstrap>", line 1176, in _find_and_load
2025-10-23T21:30:32.420984914Z [err]    File "<frozen importlib._bootstrap>", line 1147, in _find_and_load_unlocked
2025-10-23T21:30:32.420990303Z [err]    File "<frozen importlib._bootstrap>", line 690, in _load_unlocked
2025-10-23T21:30:32.420995416Z [err]    File "<frozen importlib._bootstrap_external>", line 940, in exec_module
2025-10-23T21:30:32.421000757Z [err]    File "<frozen importlib._bootstrap>", line 241, in _call_with_frames_removed
2025-10-23T21:30:32.421005944Z [err]    File "/app/app/main.py", line 20, in <module>
2025-10-23T21:30:32.421013984Z [err]      from app.api.gdrive_ops import router as gdrive_router # New import for Google Drive
2025-10-23T21:30:32.421021065Z [err]      ^^^^^^^^^^^^^^^^^^^^^^^^^^^^^^^^^^^^^^^^^^^^^^^^^^^^^^
2025-10-23T21:30:32.421026024Z [err]    File "/app/app/api/gdrive_ops/router.py", line 2, in <module>
2025-10-23T21:30:32.421031814Z [err]      from .sync import run_google_drive_sync
2025-10-23T21:30:32.421039306Z [err]    File "/app/app/api/gdrive_ops/sync.py", line 12, in <module>
2025-10-23T21:30:32.421044791Z [err]      from app.api.file_ops.upload import upload_file_to_supabase
2025-10-23T21:30:32.421051971Z [err]  ImportError: cannot import name 'upload_file_to_supabase' from 'app.api.file_ops.upload' (/app/app/api/file_ops/upload.py)
2025-10-23T21:30:37.165924316Z [err]             ^^^^^^^^^^^^^^^^^^^^^^^^^^
2025-10-23T21:30:37.165934990Z [err]    File "/usr/local/lib/python3.11/site-packages/click/core.py", line 1383, in main
2025-10-23T21:30:37.165936206Z [err]      run(
2025-10-23T21:30:37.165946678Z [err]      rv = self.invoke(ctx)
2025-10-23T21:30:37.165951440Z [err]    File "/usr/local/lib/python3.11/site-packages/uvicorn/main.py", line 593, in run
2025-10-23T21:30:37.165956532Z [err]      return ctx.invoke(self.callback, **ctx.params)
2025-10-23T21:30:37.165959587Z [err]    File "/usr/local/bin/uvicorn", line 8, in <module>
2025-10-23T21:30:37.165960408Z [err]           ^^^^^^^^^^^^^^^^
2025-10-23T21:30:37.165964378Z [err]      server.run()
2025-10-23T21:30:37.165969598Z [err]             ^^^^^^^^^^^^^^^^^^^^^^^^^^^^^^^^^^^^^^^
2025-10-23T21:30:37.165973180Z [err]    File "/usr/local/lib/python3.11/site-packages/click/core.py", line 1246, in invoke
2025-10-23T21:30:37.165978356Z [err]      sys.exit(main())
2025-10-23T21:30:37.165983055Z [err]    File "/usr/local/lib/python3.11/site-packages/click/core.py", line 814, in invoke
2025-10-23T21:30:37.165988321Z [err]  Traceback (most recent call last):
2025-10-23T21:30:37.165989536Z [err]               ^^^^^^
2025-10-23T21:30:37.165997329Z [err]      return callback(*args, **kwargs)
2025-10-23T21:30:37.166004963Z [err]             ^^^^^^^^^^^^^^^^^^^^^^^^^
2025-10-23T21:30:37.166011286Z [err]    File "/usr/local/lib/python3.11/site-packages/uvicorn/main.py", line 423, in main
2025-10-23T21:30:37.166113611Z [err]    File "/usr/local/lib/python3.11/site-packages/click/core.py", line 1462, in __call__
2025-10-23T21:30:37.166120066Z [err]      return self.main(*args, **kwargs)
2025-10-23T21:30:37.170778603Z [err]    File "/usr/local/lib/python3.11/site-packages/uvicorn/server.py", line 67, in run
2025-10-23T21:30:37.170786798Z [err]      return asyncio_run(self.serve(sockets=sockets), loop_factory=self.config.get_loop_factory())
2025-10-23T21:30:37.170966534Z [err]    File "/usr/local/lib/python3.11/asyncio/runners.py", line 118, in run
2025-10-23T21:30:37.170976579Z [err]      return self._loop.run_until_complete(task)
2025-10-23T21:30:37.170988784Z [err]             ^^^^^^^^^^^^^^^^^^^^^^^^^^^^^^^^^^^
2025-10-23T21:30:37.170996911Z [err]    File "/usr/local/lib/python3.11/asyncio/base_events.py", line 654, in run_until_complete
2025-10-23T21:30:37.171003436Z [err]      return future.result()
2025-10-23T21:30:37.171019184Z [err]             ^^^^^^^^^^^^^^^^^^^^^^^^^^^^^^^^^^^^^^^^^^^^^^^^^^^^^^^^^^^^^^^^^^^^^^^^^^^^^^^^^^^^^
2025-10-23T21:30:37.171027102Z [err]    File "/usr/local/lib/python3.11/site-packages/uvicorn/_compat.py", line 30, in asyncio_run
2025-10-23T21:30:37.171063872Z [err]      return runner.run(main)
2025-10-23T21:30:37.171073710Z [err]             ^^^^^^^^^^^^^^^^
2025-10-23T21:30:37.171077002Z [err]             ^^^^^^^^^^^^^^^
2025-10-23T21:30:37.171084436Z [err]    File "/usr/local/lib/python3.11/site-packages/uvicorn/server.py", line 71, in serve
2025-10-23T21:30:37.171090445Z [err]      await self._serve(sockets)
2025-10-23T21:30:37.171095049Z [err]    File "/usr/local/lib/python3.11/site-packages/uvicorn/server.py", line 78, in _serve
2025-10-23T21:30:37.171101566Z [err]      config.load()
2025-10-23T21:30:37.171102258Z [err]    File "/usr/local/lib/python3.11/site-packages/uvicorn/config.py", line 439, in load
2025-10-23T21:30:37.171112117Z [err]      self.loaded_app = import_from_string(self.app)
2025-10-23T21:30:37.171118210Z [err]                        ^^^^^^^^^^^^^^^^^^^^^^^^^^^^
2025-10-23T21:30:37.171128516Z [err]    File "/usr/local/lib/python3.11/site-packages/uvicorn/importer.py", line 19, in import_from_string
2025-10-23T21:30:37.171134019Z [err]      module = importlib.import_module(module_str)
2025-10-23T21:30:37.171139603Z [err]               ^^^^^^^^^^^^^^^^^^^^^^^^^^^^^^^^^^^
2025-10-23T21:30:37.171144839Z [err]    File "/usr/local/lib/python3.11/importlib/__init__.py", line 126, in import_module
2025-10-23T21:30:37.174261071Z [err]    File "<frozen importlib._bootstrap>", line 241, in _call_with_frames_removed
2025-10-23T21:30:37.174271552Z [err]    File "/app/app/main.py", line 20, in <module>
2025-10-23T21:30:37.174278236Z [err]      from app.api.gdrive_ops import router as gdrive_router # New import for Google Drive
2025-10-23T21:30:37.174350163Z [err]      return _bootstrap._gcd_import(name[level:], package, level)
2025-10-23T21:30:37.174356300Z [err]             ^^^^^^^^^^^^^^^^^^^^^^^^^^^^^^^^^^^^^^^^^^^^^^^^^^^^
2025-10-23T21:30:37.174363836Z [err]    File "<frozen importlib._bootstrap>", line 1204, in _gcd_import
2025-10-23T21:30:37.174370390Z [err]    File "<frozen importlib._bootstrap>", line 1176, in _find_and_load
2025-10-23T21:30:37.174377142Z [err]    File "<frozen importlib._bootstrap>", line 1147, in _find_and_load_unlocked
2025-10-23T21:30:37.174385534Z [err]    File "<frozen importlib._bootstrap>", line 690, in _load_unlocked
2025-10-23T21:30:37.174392722Z [err]    File "<frozen importlib._bootstrap_external>", line 940, in exec_module
2025-10-23T21:30:37.174414270Z [err]      ^^^^^^^^^^^^^^^^^^^^^^^^^^^^^^^^^^^^^^^^^^^^^^^^^^^^^^
2025-10-23T21:30:37.174420821Z [err]    File "/app/app/api/gdrive_ops/router.py", line 2, in <module>
2025-10-23T21:30:37.174428025Z [err]      from .sync import run_google_drive_sync
2025-10-23T21:30:37.174433964Z [err]    File "/app/app/api/gdrive_ops/sync.py", line 12, in <module>
2025-10-23T21:30:37.174440444Z [err]      from app.api.file_ops.upload import upload_file_to_supabase
2025-10-23T21:30:37.174447752Z [err]  ImportError: cannot import name 'upload_file_to_supabase' from 'app.api.file_ops.upload' (/app/app/api/file_ops/upload.py)
2025-10-23T21:30:41.245589061Z [err]  Traceback (most recent call last):
2025-10-23T21:30:41.245596289Z [err]    File "/usr/local/bin/uvicorn", line 8, in <module>
2025-10-23T21:30:41.245603924Z [err]      sys.exit(main())
2025-10-23T21:30:41.245612182Z [err]               ^^^^^^
2025-10-23T21:30:41.245618736Z [err]    File "/usr/local/lib/python3.11/site-packages/click/core.py", line 1462, in __call__
2025-10-23T21:30:41.245626315Z [err]      return self.main(*args, **kwargs)
2025-10-23T21:30:41.245633786Z [err]             ^^^^^^^^^^^^^^^^^^^^^^^^^^
2025-10-23T21:30:41.245641346Z [err]    File "/usr/local/lib/python3.11/site-packages/click/core.py", line 1383, in main
2025-10-23T21:30:41.245649010Z [err]      rv = self.invoke(ctx)
2025-10-23T21:30:41.245657706Z [err]           ^^^^^^^^^^^^^^^^
2025-10-23T21:30:41.245665784Z [err]    File "/usr/local/lib/python3.11/site-packages/click/core.py", line 1246, in invoke
2025-10-23T21:30:41.245672108Z [err]      return ctx.invoke(self.callback, **ctx.params)
2025-10-23T21:30:41.245677675Z [err]             ^^^^^^^^^^^^^^^^^^^^^^^^^^^^^^^^^^^^^^^
2025-10-23T21:30:41.245684906Z [err]    File "/usr/local/lib/python3.11/site-packages/click/core.py", line 814, in invoke
2025-10-23T21:30:41.245692862Z [err]      return callback(*args, **kwargs)
2025-10-23T21:30:41.245700402Z [err]             ^^^^^^^^^^^^^^^^^^^^^^^^^
2025-10-23T21:30:41.245709641Z [err]    File "/usr/local/lib/python3.11/site-packages/uvicorn/main.py", line 423, in main
2025-10-23T21:30:41.245717721Z [err]      run(
2025-10-23T21:30:41.245725779Z [err]    File "/usr/local/lib/python3.11/site-packages/uvicorn/main.py", line 593, in run
2025-10-23T21:30:41.245732885Z [err]      server.run()
2025-10-23T21:30:41.245740705Z [err]    File "/usr/local/lib/python3.11/site-packages/uvicorn/server.py", line 67, in run
2025-10-23T21:30:41.245752865Z [err]      return asyncio_run(self.serve(sockets=sockets), loop_factory=self.config.get_loop_factory())
2025-10-23T21:30:41.247009510Z [err]             ^^^^^^^^^^^^^^^^^^^^^^^^^^^^^^^^^^^^^^^^^^^^^^^^^^^^^^^^^^^^^^^^^^^^^^^^^^^^^^^^^^^^^
2025-10-23T21:30:41.247015849Z [err]    File "/usr/local/lib/python3.11/site-packages/uvicorn/_compat.py", line 30, in asyncio_run
2025-10-23T21:30:41.247021090Z [err]      return runner.run(main)
2025-10-23T21:30:41.247027659Z [err]             ^^^^^^^^^^^^^^^^
2025-10-23T21:30:41.247034343Z [err]    File "/usr/local/lib/python3.11/asyncio/runners.py", line 118, in run
2025-10-23T21:30:41.247040218Z [err]      return self._loop.run_until_complete(task)
2025-10-23T21:30:41.247046272Z [err]             ^^^^^^^^^^^^^^^^^^^^^^^^^^^^^^^^^^^
2025-10-23T21:30:41.247052183Z [err]    File "/usr/local/lib/python3.11/asyncio/base_events.py", line 654, in run_until_complete
2025-10-23T21:30:41.247060342Z [err]      return future.result()
2025-10-23T21:30:41.247065950Z [err]             ^^^^^^^^^^^^^^^
2025-10-23T21:30:41.247072083Z [err]    File "/usr/local/lib/python3.11/site-packages/uvicorn/server.py", line 71, in serve
2025-10-23T21:30:41.247078132Z [err]      await self._serve(sockets)
2025-10-23T21:30:41.247084818Z [err]    File "/usr/local/lib/python3.11/site-packages/uvicorn/server.py", line 78, in _serve
2025-10-23T21:30:41.247094375Z [err]      config.load()
2025-10-23T21:30:41.247100071Z [err]    File "/usr/local/lib/python3.11/site-packages/uvicorn/config.py", line 439, in load
2025-10-23T21:30:41.247105618Z [err]      self.loaded_app = import_from_string(self.app)
2025-10-23T21:30:41.247112550Z [err]                        ^^^^^^^^^^^^^^^^^^^^^^^^^^^^
2025-10-23T21:30:41.247118021Z [err]    File "/usr/local/lib/python3.11/site-packages/uvicorn/importer.py", line 19, in import_from_string
2025-10-23T21:30:41.247123414Z [err]      module = importlib.import_module(module_str)
2025-10-23T21:30:41.247129889Z [err]               ^^^^^^^^^^^^^^^^^^^^^^^^^^^^^^^^^^^
2025-10-23T21:30:41.247136764Z [err]    File "/usr/local/lib/python3.11/importlib/__init__.py", line 126, in import_module
2025-10-23T21:30:41.248946992Z [err]      from app.api.file_ops.upload import upload_file_to_supabase
2025-10-23T21:30:41.248954252Z [err]  ImportError: cannot import name 'upload_file_to_supabase' from 'app.api.file_ops.upload' (/app/app/api/file_ops/upload.py)
2025-10-23T21:30:41.248961223Z [err]      return _bootstrap._gcd_import(name[level:], package, level)
2025-10-23T21:30:41.248962504Z [err]    File "/app/app/main.py", line 20, in <module>
2025-10-23T21:30:41.248964606Z [err]    File "/app/app/api/gdrive_ops/router.py", line 2, in <module>
2025-10-23T21:30:41.248969511Z [err]      from .sync import run_google_drive_sync
2025-10-23T21:30:41.248974750Z [err]    File "/app/app/api/gdrive_ops/sync.py", line 12, in <module>
2025-10-23T21:30:41.248975032Z [err]      from app.api.gdrive_ops import router as gdrive_router # New import for Google Drive
2025-10-23T21:30:41.248975891Z [err]             ^^^^^^^^^^^^^^^^^^^^^^^^^^^^^^^^^^^^^^^^^^^^^^^^^^^^
2025-10-23T21:30:41.248983812Z [err]      ^^^^^^^^^^^^^^^^^^^^^^^^^^^^^^^^^^^^^^^^^^^^^^^^^^^^^^
2025-10-23T21:30:41.248984036Z [err]    File "<frozen importlib._bootstrap>", line 1204, in _gcd_import
2025-10-23T21:30:41.248989772Z [err]    File "<frozen importlib._bootstrap>", line 1176, in _find_and_load
2025-10-23T21:30:41.248995121Z [err]    File "<frozen importlib._bootstrap>", line 1147, in _find_and_load_unlocked
2025-10-23T21:30:41.249000940Z [err]    File "<frozen importlib._bootstrap>", line 690, in _load_unlocked
2025-10-23T21:30:41.249006074Z [err]    File "<frozen importlib._bootstrap_external>", line 940, in exec_module
2025-10-23T21:30:41.249010743Z [err]    File "<frozen importlib._bootstrap>", line 241, in _call_with_frames_removed
2025-10-23T21:30:46.246260843Z [err]  Traceback (most recent call last):
2025-10-23T21:30:46.246266953Z [err]    File "/usr/local/bin/uvicorn", line 8, in <module>
2025-10-23T21:30:46.246272936Z [err]      sys.exit(main())
2025-10-23T21:30:46.246278736Z [err]               ^^^^^^
2025-10-23T21:30:46.246285885Z [err]    File "/usr/local/lib/python3.11/site-packages/click/core.py", line 1462, in __call__
2025-10-23T21:30:46.246291679Z [err]      return self.main(*args, **kwargs)
2025-10-23T21:30:46.246297916Z [err]             ^^^^^^^^^^^^^^^^^^^^^^^^^^
2025-10-23T21:30:46.246303810Z [err]    File "/usr/local/lib/python3.11/site-packages/click/core.py", line 1383, in main
2025-10-23T21:30:46.246309111Z [err]      rv = self.invoke(ctx)
2025-10-23T21:30:46.246315353Z [err]           ^^^^^^^^^^^^^^^^
2025-10-23T21:30:46.246321292Z [err]    File "/usr/local/lib/python3.11/site-packages/click/core.py", line 1246, in invoke
2025-10-23T21:30:46.246327344Z [err]      return ctx.invoke(self.callback, **ctx.params)
2025-10-23T21:30:46.246334512Z [err]             ^^^^^^^^^^^^^^^^^^^^^^^^^^^^^^^^^^^^^^^
2025-10-23T21:30:46.246339880Z [err]    File "/usr/local/lib/python3.11/site-packages/click/core.py", line 814, in invoke
2025-10-23T21:30:46.246346685Z [err]      return callback(*args, **kwargs)
2025-10-23T21:30:46.246352406Z [err]             ^^^^^^^^^^^^^^^^^^^^^^^^^
2025-10-23T21:30:46.246357700Z [err]    File "/usr/local/lib/python3.11/site-packages/uvicorn/main.py", line 423, in main
2025-10-23T21:30:46.246363074Z [err]      run(
2025-10-23T21:30:46.246368861Z [err]    File "/usr/local/lib/python3.11/site-packages/uvicorn/main.py", line 593, in run
2025-10-23T21:30:46.246374097Z [err]      server.run()
2025-10-23T21:30:46.246379548Z [err]    File "/usr/local/lib/python3.11/site-packages/uvicorn/server.py", line 67, in run
2025-10-23T21:30:46.246385518Z [err]      return asyncio_run(self.serve(sockets=sockets), loop_factory=self.config.get_loop_factory())
2025-10-23T21:30:46.251971516Z [err]               ^^^^^^^^^^^^^^^^^^^^^^^^^^^^^^^^^^^
2025-10-23T21:30:46.251984136Z [err]    File "/usr/local/lib/python3.11/importlib/__init__.py", line 126, in import_module
2025-10-23T21:30:46.251999125Z [err]             ^^^^^^^^^^^^^^^^^^^^^^^^^^^^^^^^^^^^^^^^^^^^^^^^^^^^^^^^^^^^^^^^^^^^^^^^^^^^^^^^^^^^^
2025-10-23T21:30:46.252006324Z [err]    File "/usr/local/lib/python3.11/site-packages/uvicorn/_compat.py", line 30, in asyncio_run
2025-10-23T21:30:46.252012947Z [err]      return runner.run(main)
2025-10-23T21:30:46.252019257Z [err]             ^^^^^^^^^^^^^^^^
2025-10-23T21:30:46.252025855Z [err]    File "/usr/local/lib/python3.11/asyncio/runners.py", line 118, in run
2025-10-23T21:30:46.252032935Z [err]      return self._loop.run_until_complete(task)
2025-10-23T21:30:46.252040160Z [err]             ^^^^^^^^^^^^^^^^^^^^^^^^^^^^^^^^^^^
2025-10-23T21:30:46.252046867Z [err]    File "/usr/local/lib/python3.11/asyncio/base_events.py", line 654, in run_until_complete
2025-10-23T21:30:46.252053817Z [err]      return future.result()
2025-10-23T21:30:46.252060500Z [err]             ^^^^^^^^^^^^^^^
2025-10-23T21:30:46.252066988Z [err]    File "/usr/local/lib/python3.11/site-packages/uvicorn/server.py", line 71, in serve
2025-10-23T21:30:46.252073627Z [err]      await self._serve(sockets)
2025-10-23T21:30:46.252080133Z [err]    File "/usr/local/lib/python3.11/site-packages/uvicorn/server.py", line 78, in _serve
2025-10-23T21:30:46.252086196Z [err]      config.load()
2025-10-23T21:30:46.252093068Z [err]    File "/usr/local/lib/python3.11/site-packages/uvicorn/config.py", line 439, in load
2025-10-23T21:30:46.252100433Z [err]      self.loaded_app = import_from_string(self.app)
2025-10-23T21:30:46.252107194Z [err]                        ^^^^^^^^^^^^^^^^^^^^^^^^^^^^
2025-10-23T21:30:46.252120276Z [err]    File "/usr/local/lib/python3.11/site-packages/uvicorn/importer.py", line 19, in import_from_string
2025-10-23T21:30:46.252130280Z [err]      module = importlib.import_module(module_str)
2025-10-23T21:30:46.254272348Z [err]      return _bootstrap._gcd_import(name[level:], package, level)
2025-10-23T21:30:46.254279654Z [err]             ^^^^^^^^^^^^^^^^^^^^^^^^^^^^^^^^^^^^^^^^^^^^^^^^^^^^
2025-10-23T21:30:46.254285027Z [err]    File "<frozen importlib._bootstrap>", line 1204, in _gcd_import
2025-10-23T21:30:46.254289543Z [err]    File "<frozen importlib._bootstrap>", line 1176, in _find_and_load
2025-10-23T21:30:46.254294014Z [err]    File "<frozen importlib._bootstrap>", line 1147, in _find_and_load_unlocked
2025-10-23T21:30:46.254298736Z [err]    File "<frozen importlib._bootstrap>", line 690, in _load_unlocked
2025-10-23T21:30:46.254303198Z [err]    File "<frozen importlib._bootstrap_external>", line 940, in exec_module
2025-10-23T21:30:46.254307550Z [err]    File "<frozen importlib._bootstrap>", line 241, in _call_with_frames_removed
2025-10-23T21:30:46.254311548Z [err]    File "/app/app/main.py", line 20, in <module>
2025-10-23T21:30:46.254315175Z [err]      from app.api.gdrive_ops import router as gdrive_router # New import for Google Drive
2025-10-23T21:30:46.254320151Z [err]      ^^^^^^^^^^^^^^^^^^^^^^^^^^^^^^^^^^^^^^^^^^^^^^^^^^^^^^
2025-10-23T21:30:46.254325770Z [err]    File "/app/app/api/gdrive_ops/router.py", line 2, in <module>
2025-10-23T21:30:46.254332386Z [err]      from .sync import run_google_drive_sync
2025-10-23T21:30:46.254337326Z [err]    File "/app/app/api/gdrive_ops/sync.py", line 12, in <module>
2025-10-23T21:30:46.254344591Z [err]      from app.api.file_ops.upload import upload_file_to_supabase
2025-10-23T21:30:46.254350405Z [err]  ImportError: cannot import name 'upload_file_to_supabase' from 'app.api.file_ops.upload' (/app/app/api/file_ops/upload.py)
2025-10-23T21:30:50.254171297Z [err]             ^^^^^^^^^^^^^^^^^^^^^^^^^^
2025-10-23T21:30:50.254216277Z [err]    File "/usr/local/bin/uvicorn", line 8, in <module>
2025-10-23T21:30:50.254223081Z [err]      sys.exit(main())
2025-10-23T21:30:50.254233573Z [err]               ^^^^^^
2025-10-23T21:30:50.254243282Z [err]  Traceback (most recent call last):
2025-10-23T21:30:50.254264925Z [err]    File "/usr/local/lib/python3.11/site-packages/click/core.py", line 1462, in __call__
2025-10-23T21:30:50.254281505Z [err]      return self.main(*args, **kwargs)
2025-10-23T21:30:50.254296325Z [err]      return callback(*args, **kwargs)
2025-10-23T21:30:50.254297626Z [err]    File "/usr/local/lib/python3.11/site-packages/click/core.py", line 1383, in main
2025-10-23T21:30:50.254310525Z [err]      rv = self.invoke(ctx)
2025-10-23T21:30:50.254311613Z [err]             ^^^^^^^^^^^^^^^^^^^^^^^^^
2025-10-23T21:30:50.254322773Z [err]           ^^^^^^^^^^^^^^^^
2025-10-23T21:30:50.254330023Z [err]    File "/usr/local/lib/python3.11/site-packages/uvicorn/main.py", line 423, in main
2025-10-23T21:30:50.254335085Z [err]    File "/usr/local/lib/python3.11/site-packages/click/core.py", line 1246, in invoke
2025-10-23T21:30:50.254342135Z [err]      return asyncio_run(self.serve(sockets=sockets), loop_factory=self.config.get_loop_factory())
2025-10-23T21:30:50.254345602Z [err]      run(
2025-10-23T21:30:50.254346175Z [err]      return ctx.invoke(self.callback, **ctx.params)
2025-10-23T21:30:50.254360497Z [err]             ^^^^^^^^^^^^^^^^^^^^^^^^^^^^^^^^^^^^^^^
2025-10-23T21:30:50.254360833Z [err]    File "/usr/local/lib/python3.11/site-packages/uvicorn/main.py", line 593, in run
2025-10-23T21:30:50.254375124Z [err]    File "/usr/local/lib/python3.11/site-packages/click/core.py", line 814, in invoke
2025-10-23T21:30:50.254377968Z [err]      server.run()
2025-10-23T21:30:50.254387323Z [err]    File "/usr/local/lib/python3.11/site-packages/uvicorn/server.py", line 67, in run
2025-10-23T21:30:50.260729192Z [err]    File "<frozen importlib._bootstrap>", line 241, in _call_with_frames_removed
2025-10-23T21:30:50.260735688Z [err]    File "/app/app/api/gdrive_ops/router.py", line 2, in <module>
2025-10-23T21:30:50.260741442Z [err]    File "/app/app/main.py", line 20, in <module>
2025-10-23T21:30:50.260747478Z [err]    File "<frozen importlib._bootstrap>", line 1176, in _find_and_load
2025-10-23T21:30:50.260748426Z [err]      from .sync import run_google_drive_sync
2025-10-23T21:30:50.260752460Z [err]      from app.api.gdrive_ops import router as gdrive_router # New import for Google Drive
2025-10-23T21:30:50.260764021Z [err]      return _bootstrap._gcd_import(name[level:], package, level)
2025-10-23T21:30:50.260764174Z [err]    File "/app/app/api/gdrive_ops/sync.py", line 12, in <module>
2025-10-23T21:30:50.260766305Z [err]    File "<frozen importlib._bootstrap>", line 1147, in _find_and_load_unlocked
2025-10-23T21:30:50.260767102Z [err]      ^^^^^^^^^^^^^^^^^^^^^^^^^^^^^^^^^^^^^^^^^^^^^^^^^^^^^^
2025-10-23T21:30:50.260775565Z [err]      from app.api.file_ops.upload import upload_file_to_supabase
2025-10-23T21:30:50.260780856Z [err]             ^^^^^^^^^^^^^^^^^^^^^^^^^^^^^^^^^^^^^^^^^^^^^^^^^^^^
2025-10-23T21:30:50.260782548Z [err]    File "<frozen importlib._bootstrap>", line 690, in _load_unlocked
2025-10-23T21:30:50.260784039Z [err]  ImportError: cannot import name 'upload_file_to_supabase' from 'app.api.file_ops.upload' (/app/app/api/file_ops/upload.py)
2025-10-23T21:30:50.260793711Z [err]    File "<frozen importlib._bootstrap>", line 1204, in _gcd_import
2025-10-23T21:30:50.260799300Z [err]    File "<frozen importlib._bootstrap_external>", line 940, in exec_module
2025-10-23T21:30:50.260821641Z [err]             ^^^^^^^^^^^^^^^^^^^^^^^^^^^^^^^^^^^^^^^^^^^^^^^^^^^^^^^^^^^^^^^^^^^^^^^^^^^^^^^^^^^^^
2025-10-23T21:30:50.260826101Z [err]    File "/usr/local/lib/python3.11/site-packages/uvicorn/_compat.py", line 30, in asyncio_run
2025-10-23T21:30:50.260831036Z [err]      return runner.run(main)
2025-10-23T21:30:50.260836127Z [err]             ^^^^^^^^^^^^^^^^
2025-10-23T21:30:50.260840576Z [err]    File "/usr/local/lib/python3.11/asyncio/runners.py", line 118, in run
2025-10-23T21:30:50.260845463Z [err]      return self._loop.run_until_complete(task)
2025-10-23T21:30:50.260849473Z [err]             ^^^^^^^^^^^^^^^^^^^^^^^^^^^^^^^^^^^
2025-10-23T21:30:50.260853409Z [err]    File "/usr/local/lib/python3.11/asyncio/base_events.py", line 654, in run_until_complete
2025-10-23T21:30:50.260857329Z [err]      return future.result()
2025-10-23T21:30:50.260861451Z [err]             ^^^^^^^^^^^^^^^
2025-10-23T21:30:50.260865153Z [err]    File "/usr/local/lib/python3.11/site-packages/uvicorn/server.py", line 71, in serve
2025-10-23T21:30:50.260869888Z [err]      await self._serve(sockets)
2025-10-23T21:30:50.260874220Z [err]    File "/usr/local/lib/python3.11/site-packages/uvicorn/server.py", line 78, in _serve
2025-10-23T21:30:50.260877981Z [err]      config.load()
2025-10-23T21:30:50.260881671Z [err]    File "/usr/local/lib/python3.11/site-packages/uvicorn/config.py", line 439, in load
2025-10-23T21:30:50.260885583Z [err]      self.loaded_app = import_from_string(self.app)
2025-10-23T21:30:50.260889704Z [err]                        ^^^^^^^^^^^^^^^^^^^^^^^^^^^^
2025-10-23T21:30:50.260894466Z [err]    File "/usr/local/lib/python3.11/site-packages/uvicorn/importer.py", line 19, in import_from_string
2025-10-23T21:30:50.260898852Z [err]      module = importlib.import_module(module_str)
2025-10-23T21:30:50.260904134Z [err]               ^^^^^^^^^^^^^^^^^^^^^^^^^^^^^^^^^^^
2025-10-23T21:30:50.260908144Z [err]    File "/usr/local/lib/python3.11/importlib/__init__.py", line 126, in import_module
2025-10-23T21:30:54.391669849Z [err]  Traceback (most recent call last):
2025-10-23T21:30:54.391674537Z [err]    File "/usr/local/bin/uvicorn", line 8, in <module>
2025-10-23T21:30:54.391679622Z [err]      sys.exit(main())
2025-10-23T21:30:54.391684554Z [err]               ^^^^^^
2025-10-23T21:30:54.391688845Z [err]    File "/usr/local/lib/python3.11/site-packages/click/core.py", line 1462, in __call__
2025-10-23T21:30:54.391693063Z [err]      return self.main(*args, **kwargs)
2025-10-23T21:30:54.391697837Z [err]             ^^^^^^^^^^^^^^^^^^^^^^^^^^
2025-10-23T21:30:54.391702833Z [err]    File "/usr/local/lib/python3.11/site-packages/click/core.py", line 1383, in main
2025-10-23T21:30:54.391710625Z [err]      rv = self.invoke(ctx)
2025-10-23T21:30:54.391721528Z [err]           ^^^^^^^^^^^^^^^^
2025-10-23T21:30:54.391727056Z [err]    File "/usr/local/lib/python3.11/site-packages/click/core.py", line 1246, in invoke
2025-10-23T21:30:54.391736140Z [err]      return ctx.invoke(self.callback, **ctx.params)
2025-10-23T21:30:54.391741794Z [err]             ^^^^^^^^^^^^^^^^^^^^^^^^^^^^^^^^^^^^^^^
2025-10-23T21:30:54.391746627Z [err]    File "/usr/local/lib/python3.11/site-packages/click/core.py", line 814, in invoke
2025-10-23T21:30:54.391751292Z [err]      return callback(*args, **kwargs)
2025-10-23T21:30:54.391756061Z [err]             ^^^^^^^^^^^^^^^^^^^^^^^^^
2025-10-23T21:30:54.391761812Z [err]    File "/usr/local/lib/python3.11/site-packages/uvicorn/main.py", line 423, in main
2025-10-23T21:30:54.391765248Z [err]    File "/usr/local/lib/python3.11/importlib/__init__.py", line 126, in import_module
2025-10-23T21:30:54.391768276Z [err]      run(
2025-10-23T21:30:54.391774016Z [err]    File "/usr/local/lib/python3.11/site-packages/uvicorn/main.py", line 593, in run
2025-10-23T21:30:54.391778632Z [err]      server.run()
2025-10-23T21:30:54.391784781Z [err]    File "/usr/local/lib/python3.11/site-packages/uvicorn/server.py", line 67, in run
2025-10-23T21:30:54.391790981Z [err]      return asyncio_run(self.serve(sockets=sockets), loop_factory=self.config.get_loop_factory())
2025-10-23T21:30:54.391820490Z [err]      return future.result()
2025-10-23T21:30:54.391832252Z [err]             ^^^^^^^^^^^^^^^
2025-10-23T21:30:54.391839287Z [err]    File "/usr/local/lib/python3.11/site-packages/uvicorn/server.py", line 71, in serve
2025-10-23T21:30:54.391868924Z [err]      config.load()
2025-10-23T21:30:54.391883416Z [err]    File "/usr/local/lib/python3.11/site-packages/uvicorn/config.py", line 439, in load
2025-10-23T21:30:54.391892053Z [err]      self.loaded_app = import_from_string(self.app)
2025-10-23T21:30:54.391901759Z [err]             ^^^^^^^^^^^^^^^^^^^^^^^^^^^^^^^^^^^^^^^^^^^^^^^^^^^^^^^^^^^^^^^^^^^^^^^^^^^^^^^^^^^^^
2025-10-23T21:30:54.391908796Z [err]                        ^^^^^^^^^^^^^^^^^^^^^^^^^^^^
2025-10-23T21:30:54.391912559Z [err]    File "/usr/local/lib/python3.11/site-packages/uvicorn/importer.py", line 19, in import_from_string
2025-10-23T21:30:54.391917424Z [err]    File "/usr/local/lib/python3.11/site-packages/uvicorn/_compat.py", line 30, in asyncio_run
2025-10-23T21:30:54.391921909Z [err]    File "/usr/local/lib/python3.11/asyncio/runners.py", line 118, in run
2025-10-23T21:30:54.391923777Z [err]      await self._serve(sockets)
2025-10-23T21:30:54.391931668Z [err]      return self._loop.run_until_complete(task)
2025-10-23T21:30:54.391932367Z [err]      return runner.run(main)
2025-10-23T21:30:54.391936826Z [err]      module = importlib.import_module(module_str)
2025-10-23T21:30:54.391937395Z [err]    File "/usr/local/lib/python3.11/site-packages/uvicorn/server.py", line 78, in _serve
2025-10-23T21:30:54.391943338Z [err]             ^^^^^^^^^^^^^^^^^^^^^^^^^^^^^^^^^^^
2025-10-23T21:30:54.391944924Z [err]             ^^^^^^^^^^^^^^^^
2025-10-23T21:30:54.391956355Z [err]               ^^^^^^^^^^^^^^^^^^^^^^^^^^^^^^^^^^^
2025-10-23T21:30:54.391960920Z [err]    File "/usr/local/lib/python3.11/asyncio/base_events.py", line 654, in run_until_complete
2025-10-23T21:30:54.395934606Z [err]      return _bootstrap._gcd_import(name[level:], package, level)
2025-10-23T21:30:54.395938825Z [err]             ^^^^^^^^^^^^^^^^^^^^^^^^^^^^^^^^^^^^^^^^^^^^^^^^^^^^
2025-10-23T21:30:54.395943096Z [err]    File "<frozen importlib._bootstrap>", line 1204, in _gcd_import
2025-10-23T21:30:54.395947806Z [err]    File "<frozen importlib._bootstrap>", line 1176, in _find_and_load
2025-10-23T21:30:54.395959433Z [err]    File "<frozen importlib._bootstrap>", line 1147, in _find_and_load_unlocked
2025-10-23T21:30:54.395963962Z [err]    File "<frozen importlib._bootstrap>", line 690, in _load_unlocked
2025-10-23T21:30:54.395970483Z [err]    File "<frozen importlib._bootstrap_external>", line 940, in exec_module
2025-10-23T21:30:54.395976480Z [err]    File "<frozen importlib._bootstrap>", line 241, in _call_with_frames_removed
2025-10-23T21:30:54.395982632Z [err]    File "/app/app/main.py", line 20, in <module>
2025-10-23T21:30:54.395987940Z [err]      from app.api.gdrive_ops import router as gdrive_router # New import for Google Drive
2025-10-23T21:30:54.395993881Z [err]      ^^^^^^^^^^^^^^^^^^^^^^^^^^^^^^^^^^^^^^^^^^^^^^^^^^^^^^
2025-10-23T21:30:54.396000010Z [err]    File "/app/app/api/gdrive_ops/router.py", line 2, in <module>
2025-10-23T21:30:54.396006313Z [err]      from .sync import run_google_drive_sync
2025-10-23T21:30:54.396013144Z [err]    File "/app/app/api/gdrive_ops/sync.py", line 12, in <module>
2025-10-23T21:30:54.396020849Z [err]      from app.api.file_ops.upload import upload_file_to_supabase
2025-10-23T21:30:54.396026221Z [err]  ImportError: cannot import name 'upload_file_to_supabase' from 'app.api.file_ops.upload' (/app/app/api/file_ops/upload.py)
2025-10-23T21:30:59.209205130Z [err]      sys.exit(main())
2025-10-23T21:30:59.209455445Z [err]  Traceback (most recent call last):
2025-10-23T21:30:59.209465848Z [err]    File "/usr/local/bin/uvicorn", line 8, in <module>
2025-10-23T21:30:59.209522409Z [err]               ^^^^^^
2025-10-23T21:30:59.209530029Z [err]    File "/usr/local/lib/python3.11/site-packages/click/core.py", line 1462, in __call__
2025-10-23T21:30:59.209537428Z [err]      return self.main(*args, **kwargs)
2025-10-23T21:30:59.209548098Z [err]             ^^^^^^^^^^^^^^^^^^^^^^^^^^
2025-10-23T21:30:59.209555341Z [err]    File "/usr/local/lib/python3.11/site-packages/click/core.py", line 1383, in main
2025-10-23T21:30:59.209562544Z [err]      rv = self.invoke(ctx)
2025-10-23T21:30:59.209569255Z [err]           ^^^^^^^^^^^^^^^^
2025-10-23T21:30:59.209575948Z [err]    File "/usr/local/lib/python3.11/site-packages/click/core.py", line 1246, in invoke
2025-10-23T21:30:59.209583484Z [err]      return ctx.invoke(self.callback, **ctx.params)
2025-10-23T21:30:59.209683545Z [err]             ^^^^^^^^^^^^^^^^^^^^^^^^^^^^^^^^^^^^^^^
2025-10-23T21:30:59.209695450Z [err]    File "/usr/local/lib/python3.11/site-packages/click/core.py", line 814, in invoke
2025-10-23T21:30:59.209701665Z [err]      return callback(*args, **kwargs)
2025-10-23T21:30:59.209707726Z [err]             ^^^^^^^^^^^^^^^^^^^^^^^^^
2025-10-23T21:30:59.209713487Z [err]    File "/usr/local/lib/python3.11/site-packages/uvicorn/main.py", line 423, in main
2025-10-23T21:30:59.209721161Z [err]      run(
2025-10-23T21:30:59.209727000Z [err]    File "/usr/local/lib/python3.11/site-packages/uvicorn/main.py", line 593, in run
2025-10-23T21:30:59.209732331Z [err]      server.run()
2025-10-23T21:30:59.209742914Z [err]    File "/usr/local/lib/python3.11/site-packages/uvicorn/server.py", line 67, in run
2025-10-23T21:30:59.209752063Z [err]      return asyncio_run(self.serve(sockets=sockets), loop_factory=self.config.get_loop_factory())
2025-10-23T21:31:00.452481775Z [err]             ^^^^^^^^^^^^^^^^^^^^^^^^^^^^^^^^^^^^^^^^^^^^^^^^^^^^^^^^^^^^^^^^^^^^^^^^^^^^^^^^^^^^^
2025-10-23T21:31:00.452487513Z [err]    File "/usr/local/lib/python3.11/site-packages/uvicorn/_compat.py", line 30, in asyncio_run
2025-10-23T21:31:00.452492643Z [err]      return runner.run(main)
2025-10-23T21:31:00.452497644Z [err]             ^^^^^^^^^^^^^^^^
2025-10-23T21:31:00.452503474Z [err]    File "/usr/local/lib/python3.11/asyncio/runners.py", line 118, in run
2025-10-23T21:31:00.452508781Z [err]      return self._loop.run_until_complete(task)
2025-10-23T21:31:00.452514695Z [err]             ^^^^^^^^^^^^^^^^^^^^^^^^^^^^^^^^^^^
2025-10-23T21:31:00.452520813Z [err]    File "/usr/local/lib/python3.11/asyncio/base_events.py", line 654, in run_until_complete
2025-10-23T21:31:00.452527112Z [err]      return future.result()
2025-10-23T21:31:00.452532474Z [err]             ^^^^^^^^^^^^^^^
2025-10-23T21:31:00.452537651Z [err]    File "/usr/local/lib/python3.11/site-packages/uvicorn/server.py", line 71, in serve
2025-10-23T21:31:00.452543217Z [err]      await self._serve(sockets)
2025-10-23T21:31:00.452563602Z [err]    File "/usr/local/lib/python3.11/site-packages/uvicorn/server.py", line 78, in _serve
2025-10-23T21:31:00.452570443Z [err]      config.load()
2025-10-23T21:31:00.452576157Z [err]    File "/usr/local/lib/python3.11/site-packages/uvicorn/config.py", line 439, in load
2025-10-23T21:31:00.452582641Z [err]      self.loaded_app = import_from_string(self.app)
2025-10-23T21:31:00.452587943Z [err]                        ^^^^^^^^^^^^^^^^^^^^^^^^^^^^
2025-10-23T21:31:00.452593462Z [err]    File "/usr/local/lib/python3.11/site-packages/uvicorn/importer.py", line 19, in import_from_string
2025-10-23T21:31:00.452599149Z [err]      module = importlib.import_module(module_str)
2025-10-23T21:31:00.452604174Z [err]               ^^^^^^^^^^^^^^^^^^^^^^^^^^^^^^^^^^^
2025-10-23T21:31:00.452609030Z [err]    File "/usr/local/lib/python3.11/importlib/__init__.py", line 126, in import_module
2025-10-23T21:31:01.326328021Z [err]      return _bootstrap._gcd_import(name[level:], package, level)
2025-10-23T21:31:01.326338253Z [err]             ^^^^^^^^^^^^^^^^^^^^^^^^^^^^^^^^^^^^^^^^^^^^^^^^^^^^
2025-10-23T21:31:01.326344972Z [err]    File "<frozen importlib._bootstrap>", line 1204, in _gcd_import
2025-10-23T21:31:01.326366413Z [err]      ^^^^^^^^^^^^^^^^^^^^^^^^^^^^^^^^^^^^^^^^^^^^^^^^^^^^^^
2025-10-23T21:31:01.326374153Z [err]    File "/app/app/api/gdrive_ops/router.py", line 2, in <module>
2025-10-23T21:31:01.326381172Z [err]      from .sync import run_google_drive_sync
2025-10-23T21:31:01.326391096Z [err]    File "<frozen importlib._bootstrap>", line 1176, in _find_and_load
2025-10-23T21:31:01.326396843Z [err]    File "<frozen importlib._bootstrap>", line 1147, in _find_and_load_unlocked
2025-10-23T21:31:01.326404246Z [err]    File "<frozen importlib._bootstrap>", line 241, in _call_with_frames_removed
2025-10-23T21:31:01.326404751Z [err]    File "<frozen importlib._bootstrap>", line 690, in _load_unlocked
2025-10-23T21:31:01.326414025Z [err]    File "<frozen importlib._bootstrap_external>", line 940, in exec_module
2025-10-23T21:31:01.326415012Z [err]    File "/app/app/main.py", line 20, in <module>
2025-10-23T21:31:01.326422736Z [err]      from app.api.gdrive_ops import router as gdrive_router # New import for Google Drive
2025-10-23T21:31:01.326434431Z [err]    File "/app/app/api/gdrive_ops/sync.py", line 12, in <module>
2025-10-23T21:31:01.326440152Z [err]      from app.api.file_ops.upload import upload_file_to_supabase
2025-10-23T21:31:01.326445421Z [err]  ImportError: cannot import name 'upload_file_to_supabase' from 'app.api.file_ops.upload' (/app/app/api/file_ops/upload.py)
2025-10-23T21:31:03.269230766Z [err]  Traceback (most recent call last):
2025-10-23T21:31:03.269238721Z [err]    File "/usr/local/bin/uvicorn", line 8, in <module>
2025-10-23T21:31:03.269246904Z [err]      sys.exit(main())
2025-10-23T21:31:03.269254345Z [err]               ^^^^^^
2025-10-23T21:31:03.269261724Z [err]    File "/usr/local/lib/python3.11/site-packages/click/core.py", line 1462, in __call__
2025-10-23T21:31:03.269269445Z [err]      return self.main(*args, **kwargs)
2025-10-23T21:31:03.269277334Z [err]             ^^^^^^^^^^^^^^^^^^^^^^^^^^
2025-10-23T21:31:03.269284233Z [err]    File "/usr/local/lib/python3.11/site-packages/click/core.py", line 1383, in main
2025-10-23T21:31:03.269292222Z [err]      rv = self.invoke(ctx)
2025-10-23T21:31:03.269299020Z [err]           ^^^^^^^^^^^^^^^^
2025-10-23T21:31:03.269307347Z [err]    File "/usr/local/lib/python3.11/site-packages/click/core.py", line 1246, in invoke
2025-10-23T21:31:03.269314917Z [err]      return ctx.invoke(self.callback, **ctx.params)
2025-10-23T21:31:03.269321993Z [err]             ^^^^^^^^^^^^^^^^^^^^^^^^^^^^^^^^^^^^^^^
2025-10-23T21:31:03.269330351Z [err]    File "/usr/local/lib/python3.11/site-packages/click/core.py", line 814, in invoke
2025-10-23T21:31:03.269336936Z [err]      return callback(*args, **kwargs)
2025-10-23T21:31:03.269343892Z [err]             ^^^^^^^^^^^^^^^^^^^^^^^^^
2025-10-23T21:31:03.269351543Z [err]    File "/usr/local/lib/python3.11/site-packages/uvicorn/main.py", line 423, in main
2025-10-23T21:31:03.269358835Z [err]      run(
2025-10-23T21:31:03.269365711Z [err]    File "/usr/local/lib/python3.11/site-packages/uvicorn/main.py", line 593, in run
2025-10-23T21:31:03.269427688Z [err]      server.run()
2025-10-23T21:31:03.269437018Z [err]    File "/usr/local/lib/python3.11/site-packages/uvicorn/server.py", line 67, in run
2025-10-23T21:31:03.269444756Z [err]      return asyncio_run(self.serve(sockets=sockets), loop_factory=self.config.get_loop_factory())
2025-10-23T21:31:03.279592873Z [err]    File "/usr/local/lib/python3.11/site-packages/uvicorn/_compat.py", line 30, in asyncio_run
2025-10-23T21:31:03.279602205Z [err]      return runner.run(main)
2025-10-23T21:31:03.279602647Z [err]    File "/usr/local/lib/python3.11/asyncio/base_events.py", line 654, in run_until_complete
2025-10-23T21:31:03.279609825Z [err]      return future.result()
2025-10-23T21:31:03.279616818Z [err]             ^^^^^^^^^^^^^^^^
2025-10-23T21:31:03.279618826Z [err]             ^^^^^^^^^^^^^^^
2025-10-23T21:31:03.279622045Z [err]             ^^^^^^^^^^^^^^^^^^^^^^^^^^^^^^^^^^^^^^^^^^^^^^^^^^^^^^^^^^^^^^^^^^^^^^^^^^^^^^^^^^^^^
2025-10-23T21:31:03.279625731Z [err]    File "/usr/local/lib/python3.11/asyncio/runners.py", line 118, in run
2025-10-23T21:31:03.279634621Z [err]      return self._loop.run_until_complete(task)
2025-10-23T21:31:03.279636131Z [err]    File "/usr/local/lib/python3.11/site-packages/uvicorn/server.py", line 71, in serve
2025-10-23T21:31:03.279644727Z [err]             ^^^^^^^^^^^^^^^^^^^^^^^^^^^^^^^^^^^
2025-10-23T21:31:03.279646129Z [err]      await self._serve(sockets)
2025-10-23T21:31:03.279649427Z [err]      config.load()
2025-10-23T21:31:03.279653780Z [err]      self.loaded_app = import_from_string(self.app)
2025-10-23T21:31:03.279663321Z [err]    File "/usr/local/lib/python3.11/site-packages/uvicorn/config.py", line 439, in load
2025-10-23T21:31:03.279666281Z [err]                        ^^^^^^^^^^^^^^^^^^^^^^^^^^^^
2025-10-23T21:31:03.279673131Z [err]    File "/usr/local/lib/python3.11/site-packages/uvicorn/importer.py", line 19, in import_from_string
2025-10-23T21:31:03.279684433Z [err]    File "/usr/local/lib/python3.11/site-packages/uvicorn/server.py", line 78, in _serve
2025-10-23T21:31:03.279688878Z [err]      module = importlib.import_module(module_str)
2025-10-23T21:31:03.279709421Z [err]               ^^^^^^^^^^^^^^^^^^^^^^^^^^^^^^^^^^^
2025-10-23T21:31:03.279722054Z [err]    File "/usr/local/lib/python3.11/importlib/__init__.py", line 126, in import_module
2025-10-23T21:31:03.282880775Z [err]      return _bootstrap._gcd_import(name[level:], package, level)
2025-10-23T21:31:03.282886443Z [err]             ^^^^^^^^^^^^^^^^^^^^^^^^^^^^^^^^^^^^^^^^^^^^^^^^^^^^
2025-10-23T21:31:03.282892252Z [err]    File "<frozen importlib._bootstrap>", line 1204, in _gcd_import
2025-10-23T21:31:03.282897011Z [err]    File "<frozen importlib._bootstrap>", line 1176, in _find_and_load
2025-10-23T21:31:03.282902923Z [err]    File "<frozen importlib._bootstrap>", line 1147, in _find_and_load_unlocked
2025-10-23T21:31:03.282907907Z [err]    File "<frozen importlib._bootstrap>", line 690, in _load_unlocked
2025-10-23T21:31:03.282913222Z [err]    File "<frozen importlib._bootstrap_external>", line 940, in exec_module
2025-10-23T21:31:03.282923837Z [err]    File "<frozen importlib._bootstrap>", line 241, in _call_with_frames_removed
2025-10-23T21:31:03.282930709Z [err]    File "/app/app/main.py", line 20, in <module>
2025-10-23T21:31:03.282937660Z [err]      from app.api.gdrive_ops import router as gdrive_router # New import for Google Drive
2025-10-23T21:31:03.282944907Z [err]      ^^^^^^^^^^^^^^^^^^^^^^^^^^^^^^^^^^^^^^^^^^^^^^^^^^^^^^
2025-10-23T21:31:03.282951459Z [err]    File "/app/app/api/gdrive_ops/router.py", line 2, in <module>
2025-10-23T21:31:03.282959291Z [err]      from .sync import run_google_drive_sync
2025-10-23T21:31:03.282966397Z [err]    File "/app/app/api/gdrive_ops/sync.py", line 12, in <module>
2025-10-23T21:31:03.282973000Z [err]      from app.api.file_ops.upload import upload_file_to_supabase
2025-10-23T21:31:03.282982583Z [err]  ImportError: cannot import name 'upload_file_to_supabase' from 'app.api.file_ops.upload' (/app/app/api/file_ops/upload.py)
2025-10-23T21:31:06.996908065Z [err]  Traceback (most recent call last):
2025-10-23T21:31:06.996920521Z [err]    File "/usr/local/bin/uvicorn", line 8, in <module>
2025-10-23T21:31:06.996931030Z [err]      sys.exit(main())
2025-10-23T21:31:06.996939589Z [err]               ^^^^^^
2025-10-23T21:31:06.996947447Z [err]    File "/usr/local/lib/python3.11/site-packages/click/core.py", line 1462, in __call__
2025-10-23T21:31:06.996953822Z [err]      return self.main(*args, **kwargs)
2025-10-23T21:31:07.000209240Z [err]             ^^^^^^^^^^^^^^^^^^^^^^^^^^
2025-10-23T21:31:07.000217398Z [err]    File "/usr/local/lib/python3.11/site-packages/click/core.py", line 1383, in main
2025-10-23T21:31:07.000223267Z [err]      rv = self.invoke(ctx)
2025-10-23T21:31:07.000227836Z [err]           ^^^^^^^^^^^^^^^^
2025-10-23T21:31:07.000232773Z [err]    File "/usr/local/lib/python3.11/site-packages/click/core.py", line 1246, in invoke
2025-10-23T21:31:07.000236881Z [err]      return ctx.invoke(self.callback, **ctx.params)
2025-10-23T21:31:07.000240779Z [err]             ^^^^^^^^^^^^^^^^^^^^^^^^^^^^^^^^^^^^^^^
2025-10-23T21:31:07.000246100Z [err]    File "/usr/local/lib/python3.11/site-packages/click/core.py", line 814, in invoke
2025-10-23T21:31:07.000250083Z [err]      return callback(*args, **kwargs)
2025-10-23T21:31:07.000255062Z [err]             ^^^^^^^^^^^^^^^^^^^^^^^^^
2025-10-23T21:31:07.000260360Z [err]    File "/usr/local/lib/python3.11/site-packages/uvicorn/main.py", line 423, in main
2025-10-23T21:31:07.000266203Z [err]      run(
2025-10-23T21:31:07.000271849Z [err]    File "/usr/local/lib/python3.11/site-packages/uvicorn/main.py", line 593, in run
2025-10-23T21:31:07.000276587Z [err]      server.run()
2025-10-23T21:31:07.000282729Z [err]    File "/usr/local/lib/python3.11/site-packages/uvicorn/server.py", line 67, in run
2025-10-23T21:31:07.000288266Z [err]      return asyncio_run(self.serve(sockets=sockets), loop_factory=self.config.get_loop_factory())
2025-10-23T21:31:07.000538053Z [err]             ^^^^^^^^^^^^^^^^^^^^^^^^^^^^^^^^^^^^^^^^^^^^^^^^^^^^^^^^^^^^^^^^^^^^^^^^^^^^^^^^^^^^^
2025-10-23T21:31:07.000541828Z [err]    File "/usr/local/lib/python3.11/site-packages/uvicorn/_compat.py", line 30, in asyncio_run
2025-10-23T21:31:07.000545587Z [err]      return runner.run(main)
2025-10-23T21:31:07.000549269Z [err]             ^^^^^^^^^^^^^^^^
2025-10-23T21:31:07.000553054Z [err]    File "/usr/local/lib/python3.11/asyncio/runners.py", line 118, in run
2025-10-23T21:31:07.000557371Z [err]      return self._loop.run_until_complete(task)
2025-10-23T21:31:07.000561423Z [err]             ^^^^^^^^^^^^^^^^^^^^^^^^^^^^^^^^^^^
2025-10-23T21:31:07.000565051Z [err]    File "/usr/local/lib/python3.11/asyncio/base_events.py", line 654, in run_until_complete
2025-10-23T21:31:07.000569047Z [err]      return future.result()
2025-10-23T21:31:07.000572776Z [err]             ^^^^^^^^^^^^^^^
2025-10-23T21:31:07.000576923Z [err]    File "/usr/local/lib/python3.11/site-packages/uvicorn/server.py", line 71, in serve
2025-10-23T21:31:07.000580551Z [err]      await self._serve(sockets)
2025-10-23T21:31:07.000584095Z [err]    File "/usr/local/lib/python3.11/site-packages/uvicorn/server.py", line 78, in _serve
2025-10-23T21:31:07.000589814Z [err]      config.load()
2025-10-23T21:31:07.000593466Z [err]    File "/usr/local/lib/python3.11/site-packages/uvicorn/config.py", line 439, in load
2025-10-23T21:31:07.000599258Z [err]      self.loaded_app = import_from_string(self.app)
2025-10-23T21:31:07.000603493Z [err]                        ^^^^^^^^^^^^^^^^^^^^^^^^^^^^
2025-10-23T21:31:07.000607116Z [err]    File "/usr/local/lib/python3.11/site-packages/uvicorn/importer.py", line 19, in import_from_string
2025-10-23T21:31:07.000611176Z [err]      module = importlib.import_module(module_str)
2025-10-23T21:31:07.000615067Z [err]               ^^^^^^^^^^^^^^^^^^^^^^^^^^^^^^^^^^^
2025-10-23T21:31:07.000619904Z [err]    File "/usr/local/lib/python3.11/importlib/__init__.py", line 126, in import_module
2025-10-23T21:31:07.001274926Z [err]      return _bootstrap._gcd_import(name[level:], package, level)
2025-10-23T21:31:07.001279297Z [err]             ^^^^^^^^^^^^^^^^^^^^^^^^^^^^^^^^^^^^^^^^^^^^^^^^^^^^
2025-10-23T21:31:07.001283253Z [err]    File "<frozen importlib._bootstrap>", line 1204, in _gcd_import
2025-10-23T21:31:07.001286892Z [err]    File "<frozen importlib._bootstrap>", line 1176, in _find_and_load
2025-10-23T21:31:07.001291484Z [err]    File "<frozen importlib._bootstrap>", line 1147, in _find_and_load_unlocked
2025-10-23T21:31:07.001295242Z [err]    File "<frozen importlib._bootstrap>", line 690, in _load_unlocked
2025-10-23T21:31:07.001299328Z [err]    File "<frozen importlib._bootstrap_external>", line 940, in exec_module
2025-10-23T21:31:07.001303526Z [err]    File "<frozen importlib._bootstrap>", line 241, in _call_with_frames_removed
2025-10-23T21:31:07.001308836Z [err]    File "/app/app/main.py", line 20, in <module>
2025-10-23T21:31:07.001313489Z [err]      from app.api.gdrive_ops import router as gdrive_router # New import for Google Drive
2025-10-23T21:31:07.001318456Z [err]      ^^^^^^^^^^^^^^^^^^^^^^^^^^^^^^^^^^^^^^^^^^^^^^^^^^^^^^
2025-10-23T21:31:07.001323810Z [err]    File "/app/app/api/gdrive_ops/router.py", line 2, in <module>
2025-10-23T21:31:07.001329929Z [err]      from .sync import run_google_drive_sync
2025-10-23T21:31:07.001335251Z [err]    File "/app/app/api/gdrive_ops/sync.py", line 12, in <module>
2025-10-23T21:31:07.001340326Z [err]      from app.api.file_ops.upload import upload_file_to_supabase
2025-10-23T21:31:07.001346273Z [err]  ImportError: cannot import name 'upload_file_to_supabase' from 'app.api.file_ops.upload' (/app/app/api/file_ops/upload.py)